Workbook

Sheet 📊 Monthly Tracker
A1: AIR Music Distribution · SEA KPI Tracker 2026/2027 | C1: Ф1 Стабілізація · PH | L1: Ф2 Оптимізація · PH | U1: Ф3 Гео-розширення · MY | AD1: Ф4 Масштаб · ID
A2: Категорія | B2: KPI Метрика | C2: M1 · Кві 26 | F2: M2 · Тра 26 | I2: M3 · Черв 26 | L2: M4 · Лип 26 | O2: M5 · Серп 26 | R2: M6 · Вер 26 | U2: M7 · Жов 26 | X2: M8 · Лис 26 | AA2: M9 · Гру 26 | AD2: M10 · Січ 27 | AG2: M11 · Лют 27 | AJ2: M12 · Бер 27
A3: 📂 Категорія | B3: 📌 KPI Метрика | C3: 🎯 План | D3: 📈 Факт | E3: % вик. | F3: 🎯 План | G3: 📈 Факт | H3: % вик. | I3: 🎯 План | J3: 📈 Факт | K3: % вик. | L3: 🎯 План | M3: 📈 Факт | N3: % вик. | O3: 🎯 План | P3: 📈 Факт | Q3: % вик. | R3: 🎯 План | S3: 📈 Факт | T3: % вик. | U3: 🎯 План | V3: 📈 Факт | W3: % вик. | X3: 🎯 План | Y3: 📈 Факт | Z3: % вик. | AA3: 🎯 План | AB3: 📈 Факт | AC3: % вик. | AD3: 🎯 План | AE3: 📈 Факт | AF3: % вик. | AG3: 🎯 План | AH3: 📈 Факт | AI3: % вик. | AJ3: 🎯 План | AK3: 📈 Факт | AL3: % вик.
A4: 🔁 Воронка | B4: Заявки (Leads), шт. | C4: 160 | D4: 128 | E4: =IFERROR(IF(C4=0,"—",IF(D4="","",D4/C4)),"—") -> 0.8 | F4: 175 | H4: =IFERROR(IF(F4=0,"—",IF(G4="","",G4/F4)),"—") | I4: 185 | K4: =IFERROR(IF(I4=0,"—",IF(J4="","",J4/I4)),"—") | L4: 185 | N4: =IFERROR(IF(L4=0,"—",IF(M4="","",M4/L4)),"—") | O4: 195 | Q4: =IFERROR(IF(O4=0,"—",IF(P4="","",P4/O4)),"—") | R4: 210 | T4: =IFERROR(IF(R4=0,"—",IF(S4="","",S4/R4)),"—") | U4: 210 | W4: =IFERROR(IF(U4=0,"—",IF(V4="","",V4/U4)),"—") | X4: 220 | Z4: =IFERROR(IF(X4=0,"—",IF(Y4="","",Y4/X4)),"—") | AA4: 235 | AC4: =IFERROR(IF(AA4=0,"—",IF(AB4="","",AB4/AA4)),"—") | AD4: 230 | AF4: =IFERROR(IF(AD4=0,"—",IF(AE4="","",AE4/AD4)),"—") | AG4: 240 | AI4: =IFERROR(IF(AG4=0,"—",IF(AH4="","",AH4/AG4)),"—") | AJ4: 250 | AL4: =IFERROR(IF(AJ4=0,"—",IF(AK4="","",AK4/AJ4)),"—")
B5: MQL (кваліф. ліди), шт. | C5: 80 | D5: 99 | E5: =IFERROR(IF(C5=0,"—",IF(D5="","",D5/C5)),"—") -> 1.2375 | F5: 90 | H5: =IFERROR(IF(F5=0,"—",IF(G5="","",G5/F5)),"—") | I5: 100 | K5: =IFERROR(IF(I5=0,"—",IF(J5="","",J5/I5)),"—") | L5: 100 | N5: =IFERROR(IF(L5=0,"—",IF(M5="","",M5/L5)),"—") | O5: 110 | Q5: =IFERROR(IF(O5=0,"—",IF(P5="","",P5/O5)),"—") | R5: 120 | T5: =IFERROR(IF(R5=0,"—",IF(S5="","",S5/R5)),"—") | U5: 120 | W5: =IFERROR(IF(U5=0,"—",IF(V5="","",V5/U5)),"—") | X5: 130 | Z5: =IFERROR(IF(X5=0,"—",IF(Y5="","",Y5/X5)),"—") | AA5: 140 | AC5: =IFERROR(IF(AA5=0,"—",IF(AB5="","",AB5/AA5)),"—") | AD5: 140 | AF5: =IFERROR(IF(AD5=0,"—",IF(AE5="","",AE5/AD5)),"—") | AG5: 150 | AI5: =IFERROR(IF(AG5=0,"—",IF(AH5="","",AH5/AG5)),"—") | AJ5: 160 | AL5: =IFERROR(IF(AJ5=0,"—",IF(AK5="","",AK5/AJ5)),"—")
B6: SQL (дзвінки / Demo), шт. | C6: 16 | D6: 24 | E6: =IFERROR(IF(C6=0,"—",IF(D6="","",D6/C6)),"—") -> 1.5 | F6: 18 | H6: =IFERROR(IF(F6=0,"—",IF(G6="","",G6/F6)),"—") | I6: 20 | K6: =IFERROR(IF(I6=0,"—",IF(J6="","",J6/I6)),"—") | L6: 22 | N6: =IFERROR(IF(L6=0,"—",IF(M6="","",M6/L6)),"—") | O6: 24 | Q6: =IFERROR(IF(O6=0,"—",IF(P6="","",P6/O6)),"—") | R6: 26 | T6: =IFERROR(IF(R6=0,"—",IF(S6="","",S6/R6)),"—") | U6: 26 | W6: =IFERROR(IF(U6=0,"—",IF(V6="","",V6/U6)),"—") | X6: 28 | Z6: =IFERROR(IF(X6=0,"—",IF(Y6="","",Y6/X6)),"—") | AA6: 30 | AC6: =IFERROR(IF(AA6=0,"—",IF(AB6="","",AB6/AA6)),"—") | AD6: 32 | AF6: =IFERROR(IF(AD6=0,"—",IF(AE6="","",AE6/AD6)),"—") | AG6: 34 | AI6: =IFERROR(IF(AG6=0,"—",IF(AH6="","",AH6/AG6)),"—") | AJ6: 36 | AL6: =IFERROR(IF(AJ6=0,"—",IF(AK6="","",AK6/AJ6)),"—")
B7: Нових платних клієнтів, шт. | C7: 4 | D7: 5 | E7: =IFERROR(IF(C7=0,"—",IF(D7="","",D7/C7)),"—") -> 1.25 | F7: 6 | H7: =IFERROR(IF(F7=0,"—",IF(G7="","",G7/F7)),"—") | I7: 7 | K7: =IFERROR(IF(I7=0,"—",IF(J7="","",J7/I7)),"—") | L7: 8 | N7: =IFERROR(IF(L7=0,"—",IF(M7="","",M7/L7)),"—") | O7: 9 | Q7: =IFERROR(IF(O7=0,"—",IF(P7="","",P7/O7)),"—") | R7: 10 | T7: =IFERROR(IF(R7=0,"—",IF(S7="","",S7/R7)),"—") | U7: 10 | W7: =IFERROR(IF(U7=0,"—",IF(V7="","",V7/U7)),"—") | X7: 10 | Z7: =IFERROR(IF(X7=0,"—",IF(Y7="","",Y7/X7)),"—") | AA7: 11 | AC7: =IFERROR(IF(AA7=0,"—",IF(AB7="","",AB7/AA7)),"—") | AD7: 12 | AF7: =IFERROR(IF(AD7=0,"—",IF(AE7="","",AE7/AD7)),"—") | AG7: 13 | AI7: =IFERROR(IF(AG7=0,"—",IF(AH7="","",AH7/AG7)),"—") | AJ7: 14 | AL7: =IFERROR(IF(AJ7=0,"—",IF(AK7="","",AK7/AJ7)),"—")
B8: Накопич. клієнтів (з 0), шт. | C8: 4 | D8: 5 | E8: =IFERROR(IF(C8=0,"—",IF(D8="","",D8/C8)),"—") -> 1.25 | F8: 10 | H8: =IFERROR(IF(F8=0,"—",IF(G8="","",G8/F8)),"—") | I8: 17 | K8: =IFERROR(IF(I8=0,"—",IF(J8="","",J8/I8)),"—") | L8: 25 | N8: =IFERROR(IF(L8=0,"—",IF(M8="","",M8/L8)),"—") | O8: 34 | Q8: =IFERROR(IF(O8=0,"—",IF(P8="","",P8/O8)),"—") | R8: 44 | T8: =IFERROR(IF(R8=0,"—",IF(S8="","",S8/R8)),"—") | U8: 54 | W8: =IFERROR(IF(U8=0,"—",IF(V8="","",V8/U8)),"—") | X8: 64 | Z8: =IFERROR(IF(X8=0,"—",IF(Y8="","",Y8/X8)),"—") | AA8: 75 | AC8: =IFERROR(IF(AA8=0,"—",IF(AB8="","",AB8/AA8)),"—") | AD8: 86 | AF8: =IFERROR(IF(AD8=0,"—",IF(AE8="","",AE8/AD8)),"—") | AG8: 98 | AI8: =IFERROR(IF(AG8=0,"—",IF(AH8="","",AH8/AG8)),"—") | AJ8: 111 | AL8: =IFERROR(IF(AJ8=0,"—",IF(AK8="","",AK8/AJ8)),"—")
B9: Конверсія Ліди → MQL, % | C9: 0.5 | D9: 0.773 | E9: =IFERROR(IF(C9=0,"—",IF(D9="","",D9/C9)),"—") -> 1.546 | F9: 0.52 | H9: =IFERROR(IF(F9=0,"—",IF(G9="","",G9/F9)),"—") | I9: 0.55 | K9: =IFERROR(IF(I9=0,"—",IF(J9="","",J9/I9)),"—") | L9: 0.55 | N9: =IFERROR(IF(L9=0,"—",IF(M9="","",M9/L9)),"—") | O9: 0.57 | Q9: =IFERROR(IF(O9=0,"—",IF(P9="","",P9/O9)),"—") | R9: 0.58 | T9: =IFERROR(IF(R9=0,"—",IF(S9="","",S9/R9)),"—") | U9: 0.58 | W9: =IFERROR(IF(U9=0,"—",IF(V9="","",V9/U9)),"—") | X9: 0.6 | Z9: =IFERROR(IF(X9=0,"—",IF(Y9="","",Y9/X9)),"—") | AA9: 0.6 | AC9: =IFERROR(IF(AA9=0,"—",IF(AB9="","",AB9/AA9)),"—") | AD9: 0.62 | AF9: =IFERROR(IF(AD9=0,"—",IF(AE9="","",AE9/AD9)),"—") | AG9: 0.63 | AI9: =IFERROR(IF(AG9=0,"—",IF(AH9="","",AH9/AG9)),"—") | AJ9: 0.65 | AL9: =IFERROR(IF(AJ9=0,"—",IF(AK9="","",AK9/AJ9)),"—")
B10: Конверсія MQL → SQL, % | C10: 0.2 | D10: 0.242 | E10: =IFERROR(IF(C10=0,"—",IF(D10="","",D10/C10)),"—") -> 1.21 | F10: 0.2 | H10: =IFERROR(IF(F10=0,"—",IF(G10="","",G10/F10)),"—") | I10: 0.22 | K10: =IFERROR(IF(I10=0,"—",IF(J10="","",J10/I10)),"—") | L10: 0.22 | N10: =IFERROR(IF(L10=0,"—",IF(M10="","",M10/L10)),"—") | O10: 0.22 | Q10: =IFERROR(IF(O10=0,"—",IF(P10="","",P10/O10)),"—") | R10: 0.22 | T10: =IFERROR(IF(R10=0,"—",IF(S10="","",S10/R10)),"—") | U10: 0.22 | W10: =IFERROR(IF(U10=0,"—",IF(V10="","",V10/U10)),"—") | X10: 0.22 | Z10: =IFERROR(IF(X10=0,"—",IF(Y10="","",Y10/X10)),"—") | AA10: 0.22 | AC10: =IFERROR(IF(AA10=0,"—",IF(AB10="","",AB10/AA10)),"—") | AD10: 0.23 | AF10: =IFERROR(IF(AD10=0,"—",IF(AE10="","",AE10/AD10)),"—") | AG10: 0.23 | AI10: =IFERROR(IF(AG10=0,"—",IF(AH10="","",AH10/AG10)),"—") | AJ10: 0.23 | AL10: =IFERROR(IF(AJ10=0,"—",IF(AK10="","",AK10/AJ10)),"—")
B11: Конверсія SQL → Клієнт, % | C11: 0.25 | D11: 0.208 | E11: =IFERROR(IF(C11=0,"—",IF(D11="","",D11/C11)),"—") -> 0.832 | F11: 0.27 | H11: =IFERROR(IF(F11=0,"—",IF(G11="","",G11/F11)),"—") | I11: 0.28 | K11: =IFERROR(IF(I11=0,"—",IF(J11="","",J11/I11)),"—") | L11: 0.3 | N11: =IFERROR(IF(L11=0,"—",IF(M11="","",M11/L11)),"—") | O11: 0.3 | Q11: =IFERROR(IF(O11=0,"—",IF(P11="","",P11/O11)),"—") | R11: 0.33 | T11: =IFERROR(IF(R11=0,"—",IF(S11="","",S11/R11)),"—") | U11: 0.33 | W11: =IFERROR(IF(U11=0,"—",IF(V11="","",V11/U11)),"—") | X11: 0.35 | Z11: =IFERROR(IF(X11=0,"—",IF(Y11="","",Y11/X11)),"—") | AA11: 0.35 | AC11: =IFERROR(IF(AA11=0,"—",IF(AB11="","",AB11/AA11)),"—") | AD11: 0.37 | AF11: =IFERROR(IF(AD11=0,"—",IF(AE11="","",AE11/AD11)),"—") | AG11: 0.38 | AI11: =IFERROR(IF(AG11=0,"—",IF(AH11="","",AH11/AG11)),"—") | AJ11: 0.4 | AL11: =IFERROR(IF(AJ11=0,"—",IF(AK11="","",AK11/AJ11)),"—")
A12: 💰 Unit Econ | B12: CAC зведений, USD | C12: 380 | D12: 267 | E12: =IFERROR(IF(C12=0,"—",IF(D12="","",D12/C12)),"—") -> 0.70263158 | F12: 370 | H12: =IFERROR(IF(F12=0,"—",IF(G12="","",G12/F12)),"—") | I12: 360 | K12: =IFERROR(IF(I12=0,"—",IF(J12="","",J12/I12)),"—") | L12: 320 | N12: =IFERROR(IF(L12=0,"—",IF(M12="","",M12/L12)),"—") | O12: 310 | Q12: =IFERROR(IF(O12=0,"—",IF(P12="","",P12/O12)),"—") | R12: 295 | T12: =IFERROR(IF(R12=0,"—",IF(S12="","",S12/R12)),"—") | U12: 270 | W12: =IFERROR(IF(U12=0,"—",IF(V12="","",V12/U12)),"—") | X12: 255 | Z12: =IFERROR(IF(X12=0,"—",IF(Y12="","",Y12/X12)),"—") | AA12: 245 | AC12: =IFERROR(IF(AA12=0,"—",IF(AB12="","",AB12/AA12)),"—") | AD12: 235 | AF12: =IFERROR(IF(AD12=0,"—",IF(AE12="","",AE12/AD12)),"—") | AG12: 225 | AI12: =IFERROR(IF(AG12=0,"—",IF(AH12="","",AH12/AG12)),"—") | AJ12: 215 | AL12: =IFERROR(IF(AJ12=0,"—",IF(AK12="","",AK12/AJ12)),"—")
B13: CPL (вартість ліда), USD | C13: 35 | D13: 10.4 | E13: =IFERROR(IF(C13=0,"—",IF(D13="","",D13/C13)),"—") -> 0.29714286 | F13: 33 | H13: =IFERROR(IF(F13=0,"—",IF(G13="","",G13/F13)),"—") | I13: 31 | K13: =IFERROR(IF(I13=0,"—",IF(J13="","",J13/I13)),"—") | L13: 30 | N13: =IFERROR(IF(L13=0,"—",IF(M13="","",M13/L13)),"—") | O13: 28 | Q13: =IFERROR(IF(O13=0,"—",IF(P13="","",P13/O13)),"—") | R13: 27 | T13: =IFERROR(IF(R13=0,"—",IF(S13="","",S13/R13)),"—") | U13: 26 | W13: =IFERROR(IF(U13=0,"—",IF(V13="","",V13/U13)),"—") | X13: 25 | Z13: =IFERROR(IF(X13=0,"—",IF(Y13="","",Y13/X13)),"—") | AA13: 24 | AC13: =IFERROR(IF(AA13=0,"—",IF(AB13="","",AB13/AA13)),"—") | AD13: 23 | AF13: =IFERROR(IF(AD13=0,"—",IF(AE13="","",AE13/AD13)),"—") | AG13: 22 | AI13: =IFERROR(IF(AG13=0,"—",IF(AH13="","",AH13/AG13)),"—") | AJ13: 20 | AL13: =IFERROR(IF(AJ13=0,"—",IF(AK13="","",AK13/AJ13)),"—")
B14: Витрати на рекламу, USD | C14: 1500 | D14: 1336.77 | E14: =IFERROR(IF(C14=0,"—",IF(D14="","",D14/C14)),"—") -> 0.89118 | F14: 1500 | H14: =IFERROR(IF(F14=0,"—",IF(G14="","",G14/F14)),"—") | I14: 1500 | K14: =IFERROR(IF(I14=0,"—",IF(J14="","",J14/I14)),"—") | L14: 1750 | N14: =IFERROR(IF(L14=0,"—",IF(M14="","",M14/L14)),"—") | O14: 1750 | Q14: =IFERROR(IF(O14=0,"—",IF(P14="","",P14/O14)),"—") | R14: 1750 | T14: =IFERROR(IF(R14=0,"—",IF(S14="","",S14/R14)),"—") | U14: 2000 | W14: =IFERROR(IF(U14=0,"—",IF(V14="","",V14/U14)),"—") | X14: 2000 | Z14: =IFERROR(IF(X14=0,"—",IF(Y14="","",Y14/X14)),"—") | AA14: 2000 | AC14: =IFERROR(IF(AA14=0,"—",IF(AB14="","",AB14/AA14)),"—") | AD14: 2250 | AF14: =IFERROR(IF(AD14=0,"—",IF(AE14="","",AE14/AD14)),"—") | AG14: 2250 | AI14: =IFERROR(IF(AG14=0,"—",IF(AH14="","",AH14/AG14)),"—") | AJ14: 2250 | AL14: =IFERROR(IF(AJ14=0,"—",IF(AK14="","",AK14/AJ14)),"—")
B15: LTV:CAC ratio | E15: =IFERROR(IF(C15=0,"—",IF(D15="","",D15/C15)),"—") -> — | H15: =IFERROR(IF(F15=0,"—",IF(G15="","",G15/F15)),"—") -> — | K15: =IFERROR(IF(I15=0,"—",IF(J15="","",J15/I15)),"—") -> — | N15: =IFERROR(IF(L15=0,"—",IF(M15="","",M15/L15)),"—") -> — | Q15: =IFERROR(IF(O15=0,"—",IF(P15="","",P15/O15)),"—") -> — | R15: 3.5 | T15: =IFERROR(IF(R15=0,"—",IF(S15="","",S15/R15)),"—") | W15: =IFERROR(IF(U15=0,"—",IF(V15="","",V15/U15)),"—") -> — | Z15: =IFERROR(IF(X15=0,"—",IF(Y15="","",Y15/X15)),"—") -> — | AA15: 4 | AC15: =IFERROR(IF(AA15=0,"—",IF(AB15="","",AB15/AA15)),"—") | AF15: =IFERROR(IF(AD15=0,"—",IF(AE15="","",AE15/AD15)),"—") -> — | AI15: =IFERROR(IF(AG15=0,"—",IF(AH15="","",AH15/AG15)),"—") -> — | AJ15: 4.5 | AL15: =IFERROR(IF(AJ15=0,"—",IF(AK15="","",AK15/AJ15)),"—")
A16: 📣 Paid Media | B16: CTR платної реклами, % | C16: 0.015 | D16: 0.0874 | E16: =IFERROR(IF(C16=0,"—",IF(D16="","",D16/C16)),"—") -> 5.8266667 | F16: 0.017 | H16: =IFERROR(IF(F16=0,"—",IF(G16="","",G16/F16)),"—") | I16: 0.018 | K16: =IFERROR(IF(I16=0,"—",IF(J16="","",J16/I16)),"—") | L16: 0.02 | N16: =IFERROR(IF(L16=0,"—",IF(M16="","",M16/L16)),"—") | O16: 0.022 | Q16: =IFERROR(IF(O16=0,"—",IF(P16="","",P16/O16)),"—") | R16: 0.025 | T16: =IFERROR(IF(R16=0,"—",IF(S16="","",S16/R16)),"—") | U16: 0.025 | W16: =IFERROR(IF(U16=0,"—",IF(V16="","",V16/U16)),"—") | X16: 0.027 | Z16: =IFERROR(IF(X16=0,"—",IF(Y16="","",Y16/X16)),"—") | AA16: 0.028 | AC16: =IFERROR(IF(AA16=0,"—",IF(AB16="","",AB16/AA16)),"—") | AD16: 0.028 | AF16: =IFERROR(IF(AD16=0,"—",IF(AE16="","",AE16/AD16)),"—") | AG16: 0.029 | AI16: =IFERROR(IF(AG16=0,"—",IF(AH16="","",AH16/AG16)),"—") | AJ16: 0.03 | AL16: =IFERROR(IF(AJ16=0,"—",IF(AK16="","",AK16/AJ16)),"—")
B17: Google: покази, тис. | C17: 200 | D17: 3 | E17: =IFERROR(IF(C17=0,"—",IF(D17="","",D17/C17)),"—") -> 0.015 | F17: 220 | H17: =IFERROR(IF(F17=0,"—",IF(G17="","",G17/F17)),"—") | I17: 240 | K17: =IFERROR(IF(I17=0,"—",IF(J17="","",J17/I17)),"—") | L17: 260 | N17: =IFERROR(IF(L17=0,"—",IF(M17="","",M17/L17)),"—") | O17: 280 | Q17: =IFERROR(IF(O17=0,"—",IF(P17="","",P17/O17)),"—") | R17: 300 | T17: =IFERROR(IF(R17=0,"—",IF(S17="","",S17/R17)),"—") | U17: 320 | W17: =IFERROR(IF(U17=0,"—",IF(V17="","",V17/U17)),"—") | X17: 340 | Z17: =IFERROR(IF(X17=0,"—",IF(Y17="","",Y17/X17)),"—") | AA17: 360 | AC17: =IFERROR(IF(AA17=0,"—",IF(AB17="","",AB17/AA17)),"—") | AD17: 380 | AF17: =IFERROR(IF(AD17=0,"—",IF(AE17="","",AE17/AD17)),"—") | AG17: 400 | AI17: =IFERROR(IF(AG17=0,"—",IF(AH17="","",AH17/AG17)),"—") | AJ17: 420 | AL17: =IFERROR(IF(AJ17=0,"—",IF(AK17="","",AK17/AJ17)),"—")
B18: Meta: охоплення (люди), тис. | C18: 50 | D18: 20 | E18: =IFERROR(IF(C18=0,"—",IF(D18="","",D18/C18)),"—") -> 0.4 | F18: 70 | H18: =IFERROR(IF(F18=0,"—",IF(G18="","",G18/F18)),"—") | I18: 90 | K18: =IFERROR(IF(I18=0,"—",IF(J18="","",J18/I18)),"—") | L18: 100 | N18: =IFERROR(IF(L18=0,"—",IF(M18="","",M18/L18)),"—") | O18: 120 | Q18: =IFERROR(IF(O18=0,"—",IF(P18="","",P18/O18)),"—") | R18: 150 | T18: =IFERROR(IF(R18=0,"—",IF(S18="","",S18/R18)),"—") | U18: 150 | W18: =IFERROR(IF(U18=0,"—",IF(V18="","",V18/U18)),"—") | X18: 180 | Z18: =IFERROR(IF(X18=0,"—",IF(Y18="","",Y18/X18)),"—") | AA18: 200 | AC18: =IFERROR(IF(AA18=0,"—",IF(AB18="","",AB18/AA18)),"—") | AD18: 220 | AF18: =IFERROR(IF(AD18=0,"—",IF(AE18="","",AE18/AD18)),"—") | AG18: 250 | AI18: =IFERROR(IF(AG18=0,"—",IF(AH18="","",AH18/AG18)),"—") | AJ18: 280 | AL18: =IFERROR(IF(AJ18=0,"—",IF(AK18="","",AK18/AJ18)),"—")
B19: TikTok: переглядів, тис. | D19: 0 | E19: =IFERROR(IF(C19=0,"—",IF(D19="","",D19/C19)),"—") -> — | F19: 30 | H19: =IFERROR(IF(F19=0,"—",IF(G19="","",G19/F19)),"—") | I19: 50 | K19: =IFERROR(IF(I19=0,"—",IF(J19="","",J19/I19)),"—") | L19: 60 | N19: =IFERROR(IF(L19=0,"—",IF(M19="","",M19/L19)),"—") | O19: 80 | Q19: =IFERROR(IF(O19=0,"—",IF(P19="","",P19/O19)),"—") | R19: 100 | T19: =IFERROR(IF(R19=0,"—",IF(S19="","",S19/R19)),"—") | U19: 100 | W19: =IFERROR(IF(U19=0,"—",IF(V19="","",V19/U19)),"—") | X19: 120 | Z19: =IFERROR(IF(X19=0,"—",IF(Y19="","",Y19/X19)),"—") | AA19: 140 | AC19: =IFERROR(IF(AA19=0,"—",IF(AB19="","",AB19/AA19)),"—") | AD19: 140 | AF19: =IFERROR(IF(AD19=0,"—",IF(AE19="","",AE19/AD19)),"—") | AG19: 160 | AI19: =IFERROR(IF(AG19=0,"—",IF(AH19="","",AH19/AG19)),"—") | AJ19: 200 | AL19: =IFERROR(IF(AJ19=0,"—",IF(AK19="","",AK19/AJ19)),"—")
A20: 🌐 Бренд | B20: Брендовий пошук: зріст, % | E20: =IFERROR(IF(C20=0,"—",IF(D20="","",D20/C20)),"—") -> — | H20: =IFERROR(IF(F20=0,"—",IF(G20="","",G20/F20)),"—") -> — | I20: 0.05 | K20: =IFERROR(IF(I20=0,"—",IF(J20="","",J20/I20)),"—") | L20: 0.08 | N20: =IFERROR(IF(L20=0,"—",IF(M20="","",M20/L20)),"—") | O20: 0.12 | Q20: =IFERROR(IF(O20=0,"—",IF(P20="","",P20/O20)),"—") | R20: 0.18 | T20: =IFERROR(IF(R20=0,"—",IF(S20="","",S20/R20)),"—") | U20: 0.25 | W20: =IFERROR(IF(U20=0,"—",IF(V20="","",V20/U20)),"—") | X20: 0.32 | Z20: =IFERROR(IF(X20=0,"—",IF(Y20="","",Y20/X20)),"—") | AA20: 0.4 | AC20: =IFERROR(IF(AA20=0,"—",IF(AB20="","",AB20/AA20)),"—") | AD20: 0.48 | AF20: =IFERROR(IF(AD20=0,"—",IF(AE20="","",AE20/AD20)),"—") | AG20: 0.57 | AI20: =IFERROR(IF(AG20=0,"—",IF(AH20="","",AH20/AG20)),"—") | AJ20: 0.65 | AL20: =IFERROR(IF(AJ20=0,"—",IF(AK20="","",AK20/AJ20)),"—")
B21: Частка прямого трафіку, % | C21: 0.05 | E21: =IFERROR(IF(C21=0,"—",IF(D21="","",D21/C21)),"—") | F21: 0.06 | H21: =IFERROR(IF(F21=0,"—",IF(G21="","",G21/F21)),"—") | I21: 0.07 | K21: =IFERROR(IF(I21=0,"—",IF(J21="","",J21/I21)),"—") | L21: 0.08 | N21: =IFERROR(IF(L21=0,"—",IF(M21="","",M21/L21)),"—") | O21: 0.1 | Q21: =IFERROR(IF(O21=0,"—",IF(P21="","",P21/O21)),"—") | R21: 0.12 | T21: =IFERROR(IF(R21=0,"—",IF(S21="","",S21/R21)),"—") | U21: 0.14 | W21: =IFERROR(IF(U21=0,"—",IF(V21="","",V21/U21)),"—") | X21: 0.16 | Z21: =IFERROR(IF(X21=0,"—",IF(Y21="","",Y21/X21)),"—") | AA21: 0.18 | AC21: =IFERROR(IF(AA21=0,"—",IF(AB21="","",AB21/AA21)),"—") | AD21: 0.2 | AF21: =IFERROR(IF(AD21=0,"—",IF(AE21="","",AE21/AD21)),"—") | AG21: 0.22 | AI21: =IFERROR(IF(AG21=0,"—",IF(AH21="","",AH21/AG21)),"—") | AJ21: 0.25 | AL21: =IFERROR(IF(AJ21=0,"—",IF(AK21="","",AK21/AJ21)),"—")
B22: Загальне охоплення (платне+орг.), тис. | C22: 100 | E22: =IFERROR(IF(C22=0,"—",IF(D22="","",D22/C22)),"—") | F22: 150 | H22: =IFERROR(IF(F22=0,"—",IF(G22="","",G22/F22)),"—") | I22: 200 | K22: =IFERROR(IF(I22=0,"—",IF(J22="","",J22/I22)),"—") | L22: 250 | N22: =IFERROR(IF(L22=0,"—",IF(M22="","",M22/L22)),"—") | O22: 300 | Q22: =IFERROR(IF(O22=0,"—",IF(P22="","",P22/O22)),"—") | R22: 350 | T22: =IFERROR(IF(R22=0,"—",IF(S22="","",S22/R22)),"—") | U22: 400 | W22: =IFERROR(IF(U22=0,"—",IF(V22="","",V22/U22)),"—") | X22: 450 | Z22: =IFERROR(IF(X22=0,"—",IF(Y22="","",Y22/X22)),"—") | AA22: 500 | AC22: =IFERROR(IF(AA22=0,"—",IF(AB22="","",AB22/AA22)),"—") | AD22: 550 | AF22: =IFERROR(IF(AD22=0,"—",IF(AE22="","",AE22/AD22)),"—") | AG22: 600 | AI22: =IFERROR(IF(AG22=0,"—",IF(AH22="","",AH22/AG22)),"—") | AJ22: 700 | AL22: =IFERROR(IF(AJ22=0,"—",IF(AK22="","",AK22/AJ22)),"—")
A23: 📱 SMM | B23: ER соцмереж (Engagement Rate), % | C23: 0.01 | E23: =IFERROR(IF(C23=0,"—",IF(D23="","",D23/C23)),"—") | F23: 0.015 | H23: =IFERROR(IF(F23=0,"—",IF(G23="","",G23/F23)),"—") | I23: 0.02 | K23: =IFERROR(IF(I23=0,"—",IF(J23="","",J23/I23)),"—") | L23: 0.025 | N23: =IFERROR(IF(L23=0,"—",IF(M23="","",M23/L23)),"—") | O23: 0.03 | Q23: =IFERROR(IF(O23=0,"—",IF(P23="","",P23/O23)),"—") | R23: 0.035 | T23: =IFERROR(IF(R23=0,"—",IF(S23="","",S23/R23)),"—") | U23: 0.04 | W23: =IFERROR(IF(U23=0,"—",IF(V23="","",V23/U23)),"—") | X23: 0.045 | Z23: =IFERROR(IF(X23=0,"—",IF(Y23="","",Y23/X23)),"—") | AA23: 0.05 | AC23: =IFERROR(IF(AA23=0,"—",IF(AB23="","",AB23/AA23)),"—") | AD23: 0.05 | AF23: =IFERROR(IF(AD23=0,"—",IF(AE23="","",AE23/AD23)),"—") | AG23: 0.055 | AI23: =IFERROR(IF(AG23=0,"—",IF(AH23="","",AH23/AG23)),"—") | AJ23: 0.06 | AL23: =IFERROR(IF(AJ23=0,"—",IF(AK23="","",AK23/AJ23)),"—")
B24: Підписники (всі платформи), шт. | C24: 200 | E24: =IFERROR(IF(C24=0,"—",IF(D24="","",D24/C24)),"—") | F24: 400 | H24: =IFERROR(IF(F24=0,"—",IF(G24="","",G24/F24)),"—") | I24: 700 | K24: =IFERROR(IF(I24=0,"—",IF(J24="","",J24/I24)),"—") | L24: 1000 | N24: =IFERROR(IF(L24=0,"—",IF(M24="","",M24/L24)),"—") | O24: 1400 | Q24: =IFERROR(IF(O24=0,"—",IF(P24="","",P24/O24)),"—") | R24: 1900 | T24: =IFERROR(IF(R24=0,"—",IF(S24="","",S24/R24)),"—") | U24: 2500 | W24: =IFERROR(IF(U24=0,"—",IF(V24="","",V24/U24)),"—") | X24: 3200 | Z24: =IFERROR(IF(X24=0,"—",IF(Y24="","",Y24/X24)),"—") | AA24: 4000 | AC24: =IFERROR(IF(AA24=0,"—",IF(AB24="","",AB24/AA24)),"—") | AD24: 4800 | AF24: =IFERROR(IF(AD24=0,"—",IF(AE24="","",AE24/AD24)),"—") | AG24: 5700 | AI24: =IFERROR(IF(AG24=0,"—",IF(AH24="","",AH24/AG24)),"—") | AJ24: 7000 | AL24: =IFERROR(IF(AJ24=0,"—",IF(AK24="","",AK24/AJ24)),"—")
A25: ✍️ Контент / PR | B25: Статей у блозі (накопич.), шт. | C25: 2 | E25: =IFERROR(IF(C25=0,"—",IF(D25="","",D25/C25)),"—") | F25: 4 | H25: =IFERROR(IF(F25=0,"—",IF(G25="","",G25/F25)),"—") | I25: 6 | K25: =IFERROR(IF(I25=0,"—",IF(J25="","",J25/I25)),"—") | L25: 8 | N25: =IFERROR(IF(L25=0,"—",IF(M25="","",M25/L25)),"—") | O25: 10 | Q25: =IFERROR(IF(O25=0,"—",IF(P25="","",P25/O25)),"—") | R25: 14 | T25: =IFERROR(IF(R25=0,"—",IF(S25="","",S25/R25)),"—") | U25: 18 | W25: =IFERROR(IF(U25=0,"—",IF(V25="","",V25/U25)),"—") | X25: 22 | Z25: =IFERROR(IF(X25=0,"—",IF(Y25="","",Y25/X25)),"—") | AA25: 26 | AC25: =IFERROR(IF(AA25=0,"—",IF(AB25="","",AB25/AA25)),"—") | AD25: 30 | AF25: =IFERROR(IF(AD25=0,"—",IF(AE25="","",AE25/AD25)),"—") | AG25: 34 | AI25: =IFERROR(IF(AG25=0,"—",IF(AH25="","",AH25/AG25)),"—") | AJ25: 38 | AL25: =IFERROR(IF(AJ25=0,"—",IF(AK25="","",AK25/AJ25)),"—")
B26: Кейс-стаді опубл. (накопич.), шт. | C26: 0 | E26: =IFERROR(IF(C26=0,"—",IF(D26="","",D26/C26)),"—") -> — | F26: 0 | H26: =IFERROR(IF(F26=0,"—",IF(G26="","",G26/F26)),"—") -> — | I26: 1 | K26: =IFERROR(IF(I26=0,"—",IF(J26="","",J26/I26)),"—") | L26: 2 | N26: =IFERROR(IF(L26=0,"—",IF(M26="","",M26/L26)),"—") | O26: 3 | Q26: =IFERROR(IF(O26=0,"—",IF(P26="","",P26/O26)),"—") | R26: 4 | T26: =IFERROR(IF(R26=0,"—",IF(S26="","",S26/R26)),"—") | U26: 5 | W26: =IFERROR(IF(U26=0,"—",IF(V26="","",V26/U26)),"—") | X26: 6 | Z26: =IFERROR(IF(X26=0,"—",IF(Y26="","",Y26/X26)),"—") | AA26: 7 | AC26: =IFERROR(IF(AA26=0,"—",IF(AB26="","",AB26/AA26)),"—") | AD26: 8 | AF26: =IFERROR(IF(AD26=0,"—",IF(AE26="","",AE26/AD26)),"—") | AG26: 9 | AI26: =IFERROR(IF(AG26=0,"—",IF(AH26="","",AH26/AG26)),"—") | AJ26: 10 | AL26: =IFERROR(IF(AJ26=0,"—",IF(AK26="","",AK26/AJ26)),"—")
B27: PR-публікації (накопич.), шт. | C27: 0 | E27: =IFERROR(IF(C27=0,"—",IF(D27="","",D27/C27)),"—") -> — | F27: 0 | H27: =IFERROR(IF(F27=0,"—",IF(G27="","",G27/F27)),"—") -> — | I27: 1 | K27: =IFERROR(IF(I27=0,"—",IF(J27="","",J27/I27)),"—") | L27: 1 | N27: =IFERROR(IF(L27=0,"—",IF(M27="","",M27/L27)),"—") | O27: 2 | Q27: =IFERROR(IF(O27=0,"—",IF(P27="","",P27/O27)),"—") | R27: 2 | T27: =IFERROR(IF(R27=0,"—",IF(S27="","",S27/R27)),"—") | U27: 3 | W27: =IFERROR(IF(U27=0,"—",IF(V27="","",V27/U27)),"—") | X27: 4 | Z27: =IFERROR(IF(X27=0,"—",IF(Y27="","",Y27/X27)),"—") | AA27: 5 | AC27: =IFERROR(IF(AA27=0,"—",IF(AB27="","",AB27/AA27)),"—") | AD27: 6 | AF27: =IFERROR(IF(AD27=0,"—",IF(AE27="","",AE27/AD27)),"—") | AG27: 7 | AI27: =IFERROR(IF(AG27=0,"—",IF(AH27="","",AH27/AG27)),"—") | AJ27: 8 | AL27: =IFERROR(IF(AJ27=0,"—",IF(AK27="","",AK27/AJ27)),"—")
A28: 📧 Email | B28: Email Open Rate (OR), % | C28: 0.25 | E28: =IFERROR(IF(C28=0,"—",IF(D28="","",D28/C28)),"—") | F28: 0.28 | H28: =IFERROR(IF(F28=0,"—",IF(G28="","",G28/F28)),"—") | I28: 0.3 | K28: =IFERROR(IF(I28=0,"—",IF(J28="","",J28/I28)),"—") | L28: 0.32 | N28: =IFERROR(IF(L28=0,"—",IF(M28="","",M28/L28)),"—") | O28: 0.33 | Q28: =IFERROR(IF(O28=0,"—",IF(P28="","",P28/O28)),"—") | R28: 0.35 | T28: =IFERROR(IF(R28=0,"—",IF(S28="","",S28/R28)),"—") | U28: 0.35 | W28: =IFERROR(IF(U28=0,"—",IF(V28="","",V28/U28)),"—") | X28: 0.36 | Z28: =IFERROR(IF(X28=0,"—",IF(Y28="","",Y28/X28)),"—") | AA28: 0.37 | AC28: =IFERROR(IF(AA28=0,"—",IF(AB28="","",AB28/AA28)),"—") | AD28: 0.37 | AF28: =IFERROR(IF(AD28=0,"—",IF(AE28="","",AE28/AD28)),"—") | AG28: 0.38 | AI28: =IFERROR(IF(AG28=0,"—",IF(AH28="","",AH28/AG28)),"—") | AJ28: 0.4 | AL28: =IFERROR(IF(AJ28=0,"—",IF(AK28="","",AK28/AJ28)),"—")
B29: Email CTR, % | C29: 0.05 | E29: =IFERROR(IF(C29=0,"—",IF(D29="","",D29/C29)),"—") | F29: 0.06 | H29: =IFERROR(IF(F29=0,"—",IF(G29="","",G29/F29)),"—") | I29: 0.07 | K29: =IFERROR(IF(I29=0,"—",IF(J29="","",J29/I29)),"—") | L29: 0.07 | N29: =IFERROR(IF(L29=0,"—",IF(M29="","",M29/L29)),"—") | O29: 0.08 | Q29: =IFERROR(IF(O29=0,"—",IF(P29="","",P29/O29)),"—") | R29: 0.08 | T29: =IFERROR(IF(R29=0,"—",IF(S29="","",S29/R29)),"—") | U29: 0.08 | W29: =IFERROR(IF(U29=0,"—",IF(V29="","",V29/U29)),"—") | X29: 0.09 | Z29: =IFERROR(IF(X29=0,"—",IF(Y29="","",Y29/X29)),"—") | AA29: 0.09 | AC29: =IFERROR(IF(AA29=0,"—",IF(AB29="","",AB29/AA29)),"—") | AD29: 0.09 | AF29: =IFERROR(IF(AD29=0,"—",IF(AE29="","",AE29/AD29)),"—") | AG29: 0.09 | AI29: =IFERROR(IF(AG29=0,"—",IF(AH29="","",AH29/AG29)),"—") | AJ29: 0.1 | AL29: =IFERROR(IF(AJ29=0,"—",IF(AK29="","",AK29/AJ29)),"—")
A30: 🔒 Утримання | B30: Утримання клієнтів 3M, % | E30: =IFERROR(IF(C30=0,"—",IF(D30="","",D30/C30)),"—") -> — | H30: =IFERROR(IF(F30=0,"—",IF(G30="","",G30/F30)),"—") -> — | I30: 0.7 | K30: =IFERROR(IF(I30=0,"—",IF(J30="","",J30/I30)),"—") | N30: =IFERROR(IF(L30=0,"—",IF(M30="","",M30/L30)),"—") -> — | Q30: =IFERROR(IF(O30=0,"—",IF(P30="","",P30/O30)),"—") -> — | R30: 0.72 | T30: =IFERROR(IF(R30=0,"—",IF(S30="","",S30/R30)),"—") | W30: =IFERROR(IF(U30=0,"—",IF(V30="","",V30/U30)),"—") -> — | Z30: =IFERROR(IF(X30=0,"—",IF(Y30="","",Y30/X30)),"—") -> — | AA30: 0.73 | AC30: =IFERROR(IF(AA30=0,"—",IF(AB30="","",AB30/AA30)),"—") | AF30: =IFERROR(IF(AD30=0,"—",IF(AE30="","",AE30/AD30)),"—") -> — | AI30: =IFERROR(IF(AG30=0,"—",IF(AH30="","",AH30/AG30)),"—") -> — | AJ30: 0.75 | AL30: =IFERROR(IF(AJ30=0,"—",IF(AK30="","",AK30/AJ30)),"—")
B31: Відгуки / Рекомендації (накопич.) | C31: 0 | E31: =IFERROR(IF(C31=0,"—",IF(D31="","",D31/C31)),"—") -> — | F31: 1 | H31: =IFERROR(IF(F31=0,"—",IF(G31="","",G31/F31)),"—") | I31: 3 | K31: =IFERROR(IF(I31=0,"—",IF(J31="","",J31/I31)),"—") | L31: 5 | N31: =IFERROR(IF(L31=0,"—",IF(M31="","",M31/L31)),"—") | O31: 8 | Q31: =IFERROR(IF(O31=0,"—",IF(P31="","",P31/O31)),"—") | R31: 12 | T31: =IFERROR(IF(R31=0,"—",IF(S31="","",S31/R31)),"—") | U31: 15 | W31: =IFERROR(IF(U31=0,"—",IF(V31="","",V31/U31)),"—") | X31: 18 | Z31: =IFERROR(IF(X31=0,"—",IF(Y31="","",Y31/X31)),"—") | AA31: 21 | AC31: =IFERROR(IF(AA31=0,"—",IF(AB31="","",AB31/AA31)),"—") | AD31: 23 | AF31: =IFERROR(IF(AD31=0,"—",IF(AE31="","",AE31/AD31)),"—") | AG31: 26 | AI31: =IFERROR(IF(AG31=0,"—",IF(AH31="","",AH31/AG31)),"—") | AJ31: 30 | AL31: =IFERROR(IF(AJ31=0,"—",IF(AK31="","",AK31/AJ31)),"—")
B32: Партнерства (накопич.), шт. | C32: 0 | E32: =IFERROR(IF(C32=0,"—",IF(D32="","",D32/C32)),"—") -> — | F32: 0 | H32: =IFERROR(IF(F32=0,"—",IF(G32="","",G32/F32)),"—") -> — | I32: 1 | K32: =IFERROR(IF(I32=0,"—",IF(J32="","",J32/I32)),"—") | L32: 1 | N32: =IFERROR(IF(L32=0,"—",IF(M32="","",M32/L32)),"—") | O32: 2 | Q32: =IFERROR(IF(O32=0,"—",IF(P32="","",P32/O32)),"—") | R32: 3 | T32: =IFERROR(IF(R32=0,"—",IF(S32="","",S32/R32)),"—") | U32: 4 | W32: =IFERROR(IF(U32=0,"—",IF(V32="","",V32/U32)),"—") | X32: 5 | Z32: =IFERROR(IF(X32=0,"—",IF(Y32="","",Y32/X32)),"—") | AA32: 6 | AC32: =IFERROR(IF(AA32=0,"—",IF(AB32="","",AB32/AA32)),"—") | AD32: 7 | AF32: =IFERROR(IF(AD32=0,"—",IF(AE32="","",AE32/AD32)),"—") | AG32: 8 | AI32: =IFERROR(IF(AG32=0,"—",IF(AH32="","",AH32/AG32)),"—") | AJ32: 10 | AL32: =IFERROR(IF(AJ32=0,"—",IF(AK32="","",AK32/AJ32)),"—")
A33: 🏁 Накопичено клієнтів (рядок 4 + підсумок) | C33: =C8 -> 4 | D33: 5 | E33: =IFERROR(IF(C33=0,"—",IF(D33="","",D33/C33)),"—") -> 1.25 | F33: =F8 -> 10 | H33: =IFERROR(IF(F33=0,"—",IF(G33="","",G33/F33)),"—") | I33: =I8 -> 17 | K33: =IFERROR(IF(I33=0,"—",IF(J33="","",J33/I33)),"—") | L33: =L8 -> 25 | N33: =IFERROR(IF(L33=0,"—",IF(M33="","",M33/L33)),"—") | O33: =O8 -> 34 | Q33: =IFERROR(IF(O33=0,"—",IF(P33="","",P33/O33)),"—") | R33: =R8 -> 44 | T33: =IFERROR(IF(R33=0,"—",IF(S33="","",S33/R33)),"—") | U33: =U8 -> 54 | W33: =IFERROR(IF(U33=0,"—",IF(V33="","",V33/U33)),"—") | X33: =X8 -> 64 | Z33: =IFERROR(IF(X33=0,"—",IF(Y33="","",Y33/X33)),"—") | AA33: =AA8 -> 75 | AC33: =IFERROR(IF(AA33=0,"—",IF(AB33="","",AB33/AA33)),"—") | AD33: =AD8 -> 86 | AF33: =IFERROR(IF(AD33=0,"—",IF(AE33="","",AE33/AD33)),"—") | AG33: =AG8 -> 98 | AI33: =IFERROR(IF(AG33=0,"—",IF(AH33="","",AH33/AG33)),"—") | AJ33: =AJ8 -> 111 | AL33: =IFERROR(IF(AJ33=0,"—",IF(AK33="","",AK33/AJ33)),"—")
A35: 📡 РОЗБИВКА ЛІДІВ ЗА КАНАЛАМИ · план та факт по місяцях
A36: 📂 Канал | B36: 📌 Метрика | C36: 🎯 План | D36: 📈 Факт | E36: % вик. | F36: 🎯 План | G36: 📈 Факт | H36: % вик. | I36: 🎯 План | J36: 📈 Факт | K36: % вик. | L36: 🎯 План | M36: 📈 Факт | N36: % вик. | O36: 🎯 План | P36: 📈 Факт | Q36: % вик. | R36: 🎯 План | S36: 📈 Факт | T36: % вик. | U36: 🎯 План | V36: 📈 Факт | W36: % вик. | X36: 🎯 План | Y36: 📈 Факт | Z36: % вик. | AA36: 🎯 План | AB36: 📈 Факт | AC36: % вик. | AD36: 🎯 План | AE36: 📈 Факт | AF36: % вик. | AG36: 🎯 План | AH36: 📈 Факт | AI36: % вик. | AJ36: 🎯 План | AK36: 📈 Факт | AL36: % вик.
A37: 🔍 Google Search Ads | B37: Ліди (заявки), шт. | C37: 61 | D37: 30 | E37: =IFERROR(IF(ISNUMBER(C37),IF(D37="","",D37/C37),"—"),"—") -> 0.49180328 | F37: 66 | H37: =IFERROR(IF(ISNUMBER(F37),IF(G37="","",G37/F37),"—"),"—") | I37: 70 | K37: =IFERROR(IF(ISNUMBER(I37),IF(J37="","",J37/I37),"—"),"—") | L37: 70 | N37: =IFERROR(IF(ISNUMBER(L37),IF(M37="","",M37/L37),"—"),"—") | O37: 74 | Q37: =IFERROR(IF(ISNUMBER(O37),IF(P37="","",P37/O37),"—"),"—") | R37: 80 | T37: =IFERROR(IF(ISNUMBER(R37),IF(S37="","",S37/R37),"—"),"—") | U37: 80 | W37: =IFERROR(IF(ISNUMBER(U37),IF(V37="","",V37/U37),"—"),"—") | X37: 83 | Z37: =IFERROR(IF(ISNUMBER(X37),IF(Y37="","",Y37/X37),"—"),"—") | AA37: 89 | AC37: =IFERROR(IF(ISNUMBER(AA37),IF(AB37="","",AB37/AA37),"—"),"—") | AD37: 87 | AF37: =IFERROR(IF(ISNUMBER(AD37),IF(AE37="","",AE37/AD37),"—"),"—") | AG37: 91 | AI37: =IFERROR(IF(ISNUMBER(AG37),IF(AH37="","",AH37/AG37),"—"),"—") | AJ37: 95 | AL37: =IFERROR(IF(ISNUMBER(AJ37),IF(AK37="","",AK37/AJ37),"—"),"—")
B38: MQL, шт. | C38: 30 | D38: 25 | E38: =IFERROR(IF(ISNUMBER(C38),IF(D38="","",D38/C38),"—"),"—") -> 0.83333333 | F38: 34 | H38: =IFERROR(IF(ISNUMBER(F38),IF(G38="","",G38/F38),"—"),"—") | I38: 38 | K38: =IFERROR(IF(ISNUMBER(I38),IF(J38="","",J38/I38),"—"),"—") | L38: 38 | N38: =IFERROR(IF(ISNUMBER(L38),IF(M38="","",M38/L38),"—"),"—") | O38: 42 | Q38: =IFERROR(IF(ISNUMBER(O38),IF(P38="","",P38/O38),"—"),"—") | R38: 45 | T38: =IFERROR(IF(ISNUMBER(R38),IF(S38="","",S38/R38),"—"),"—") | U38: 45 | W38: =IFERROR(IF(ISNUMBER(U38),IF(V38="","",V38/U38),"—"),"—") | X38: 49 | Z38: =IFERROR(IF(ISNUMBER(X38),IF(Y38="","",Y38/X38),"—"),"—") | AA38: 53 | AC38: =IFERROR(IF(ISNUMBER(AA38),IF(AB38="","",AB38/AA38),"—"),"—") | AD38: 53 | AF38: =IFERROR(IF(ISNUMBER(AD38),IF(AE38="","",AE38/AD38),"—"),"—") | AG38: 57 | AI38: =IFERROR(IF(ISNUMBER(AG38),IF(AH38="","",AH38/AG38),"—"),"—") | AJ38: 61 | AL38: =IFERROR(IF(ISNUMBER(AJ38),IF(AK38="","",AK38/AJ38),"—"),"—")
B39: SQL, шт. | C39: 6 | D39: 5 | E39: =IFERROR(IF(ISNUMBER(C39),IF(D39="","",D39/C39),"—"),"—") -> 0.83333333 | F39: 7 | H39: =IFERROR(IF(ISNUMBER(F39),IF(G39="","",G39/F39),"—"),"—") | I39: 8 | K39: =IFERROR(IF(ISNUMBER(I39),IF(J39="","",J39/I39),"—"),"—") | L39: 8 | N39: =IFERROR(IF(ISNUMBER(L39),IF(M39="","",M39/L39),"—"),"—") | O39: 9 | Q39: =IFERROR(IF(ISNUMBER(O39),IF(P39="","",P39/O39),"—"),"—") | R39: 10 | T39: =IFERROR(IF(ISNUMBER(R39),IF(S39="","",S39/R39),"—"),"—") | U39: 10 | W39: =IFERROR(IF(ISNUMBER(U39),IF(V39="","",V39/U39),"—"),"—") | X39: 11 | Z39: =IFERROR(IF(ISNUMBER(X39),IF(Y39="","",Y39/X39),"—"),"—") | AA39: 11 | AC39: =IFERROR(IF(ISNUMBER(AA39),IF(AB39="","",AB39/AA39),"—"),"—") | AD39: 12 | AF39: =IFERROR(IF(ISNUMBER(AD39),IF(AE39="","",AE39/AD39),"—"),"—") | AG39: 13 | AI39: =IFERROR(IF(ISNUMBER(AG39),IF(AH39="","",AH39/AG39),"—"),"—") | AJ39: 14 | AL39: =IFERROR(IF(ISNUMBER(AJ39),IF(AK39="","",AK39/AJ39),"—"),"—")
B40: ✅ Клієнти (контракт), шт. | C40: 2 | E40: =IFERROR(IF(ISNUMBER(C40),IF(D40="","",D40/C40),"—"),"—") | F40: 2 | H40: =IFERROR(IF(ISNUMBER(F40),IF(G40="","",G40/F40),"—"),"—") | I40: 3 | K40: =IFERROR(IF(ISNUMBER(I40),IF(J40="","",J40/I40),"—"),"—") | L40: 3 | N40: =IFERROR(IF(ISNUMBER(L40),IF(M40="","",M40/L40),"—"),"—") | O40: 3 | Q40: =IFERROR(IF(ISNUMBER(O40),IF(P40="","",P40/O40),"—"),"—") | R40: 4 | T40: =IFERROR(IF(ISNUMBER(R40),IF(S40="","",S40/R40),"—"),"—") | U40: 4 | W40: =IFERROR(IF(ISNUMBER(U40),IF(V40="","",V40/U40),"—"),"—") | X40: 4 | Z40: =IFERROR(IF(ISNUMBER(X40),IF(Y40="","",Y40/X40),"—"),"—") | AA40: 4 | AC40: =IFERROR(IF(ISNUMBER(AA40),IF(AB40="","",AB40/AA40),"—"),"—") | AD40: 5 | AF40: =IFERROR(IF(ISNUMBER(AD40),IF(AE40="","",AE40/AD40),"—"),"—") | AG40: 5 | AI40: =IFERROR(IF(ISNUMBER(AG40),IF(AH40="","",AH40/AG40),"—"),"—") | AJ40: 5 | AL40: =IFERROR(IF(ISNUMBER(AJ40),IF(AK40="","",AK40/AJ40),"—"),"—")
A41: 📘 Meta Ads | B41: Ліди (заявки), шт. | C41: 45 | D41: 27 | E41: =IFERROR(IF(ISNUMBER(C41),IF(D41="","",D41/C41),"—"),"—") -> 0.6 | F41: 50 | H41: =IFERROR(IF(ISNUMBER(F41),IF(G41="","",G41/F41),"—"),"—") | I41: 53 | K41: =IFERROR(IF(ISNUMBER(I41),IF(J41="","",J41/I41),"—"),"—") | L41: 53 | N41: =IFERROR(IF(ISNUMBER(L41),IF(M41="","",M41/L41),"—"),"—") | O41: 55 | Q41: =IFERROR(IF(ISNUMBER(O41),IF(P41="","",P41/O41),"—"),"—") | R41: 60 | T41: =IFERROR(IF(ISNUMBER(R41),IF(S41="","",S41/R41),"—"),"—") | U41: 60 | W41: =IFERROR(IF(ISNUMBER(U41),IF(V41="","",V41/U41),"—"),"—") | X41: 62 | Z41: =IFERROR(IF(ISNUMBER(X41),IF(Y41="","",Y41/X41),"—"),"—") | AA41: 67 | AC41: =IFERROR(IF(ISNUMBER(AA41),IF(AB41="","",AB41/AA41),"—"),"—") | AD41: 65 | AF41: =IFERROR(IF(ISNUMBER(AD41),IF(AE41="","",AE41/AD41),"—"),"—") | AG41: 68 | AI41: =IFERROR(IF(ISNUMBER(AG41),IF(AH41="","",AH41/AG41),"—"),"—") | AJ41: 71 | AL41: =IFERROR(IF(ISNUMBER(AJ41),IF(AK41="","",AK41/AJ41),"—"),"—")
...

Sheet 📋 Інструкція
A1: 📊 AIR Music KPI Tracker · Інструкція з використання
A3: ЯК ЗАПОВНЮВАТИ ТАБЛИЦЮ
A4: 1. Йди на лист '📊 Monthly Tracker'
A5: 2. На початку кожного місяця заповнюй колонку 📈 Факт (блакитні клітинки) по кожному KPI
A6: 3. Колонка 🎯 План заповнена заздалегідь — на основі стратегії SEA 2026/2027
A7: 4. Колонка % вик. розраховується автоматично. Нічого руками міняти не потрібно.
A8: 5. Значення плану можна коригувати якщо стратегія змінилась — це нормально
A10: КОЛЬОРОВЕ КОДУВАННЯ (умовне форматування — додати вручну при бажанні)
A11: 🟢 % виконання ≥ 90% — ціль досягнута, все добре
A12: 🟡 % виконання 70–89% — є відставання, потрібна увага
A13: 🔴 % виконання < 70% — критичне відставання, потрібен action plan
A15: ПЛАН ЗА ФАЗАМИ (зі стратегії)
... A29: 💡 Джерело плану: AIR_SEA_Marketing_Strategy_2026_v8.pptx · AIR_Music_Roadmap.xlsx

Sheet 📈 Річний підсумок
A1: AIR Music · SEA · Річний підсумок KPI 2026/2027
A2: KPI Метрика | B2: Ціль на рік | C2: Ф1 факт (M1-M3) | D2: Ф2 факт (M4-M6) | E2: Ф3 факт (M7-M9) | F2: Ф4 факт (M10-M12) | G2: Рік ФАКТ | H2: Рік ПЛАН | I2: % вик.
A3: Заявки (Leads), шт. | B3: 1,600–2,000 | C3: =IFERROR(SUM('📊 Monthly Tracker'!D7,'📊 Monthly Tracker'!G7,'📊 Monthly Tracker'!J7),"") -> 5 | D3: =IFERROR(SUM('📊 Monthly Tracker'!M7,'📊 Monthly Tracker'!P7,'📊 Monthly Tracker'!S7),"") -> 0 | E3: =IFERROR(SUM('📊 Monthly Tracker'!V7,'📊 Monthly Tracker'!Y7,'📊 Monthly Tracker'!AB7),"") -> 0 | F3: =IFERROR(SUM('📊 Monthly Tracker'!AE7,'📊 Monthly Tracker'!AH7,'📊 Monthly Tracker'!AK7),"") -> 0 | G3: =IFERROR(SUM('📊 Monthly Tracker'!D7,'📊 Monthly Tracker'!G7,'📊 Monthly Tracker'!J7,'📊 Monthly Tracker'!M7,'📊 Monthly Tracker'!P7,'📊 Monthly Tracker'!S7,'📊 Monthly Tracker'!V7,'📊 Monthly Tracker'!Y7,'📊 Monthly Tracker'!AB7,'📊 Monthly Tracker'!AE7,'📊 Monthly Tracker'!AH7,'📊 Monthly Tracker'!AK7),"") -> 5 | H3: ='📊 Monthly Tracker'!AJ7 -> 14 | I3: =IFERROR(IF(H3=0,"—",IF(G3="","",G3/H3)),"—") -> 0.35714286
A4: MQL (кваліф. ліди), шт. | B4: 1,200–1,450 | C4: =IFERROR(SUM('📊 Monthly Tracker'!D8,'📊 Monthly Tracker'!G8,'📊 Monthly Tracker'!J8),"") -> 5 | D4: =IFERROR(SUM('📊 Monthly Tracker'!M8,'📊 Monthly Tracker'!P8,'📊 Monthly Tracker'!S8),"") -> 0 | E4: =IFERROR(SUM('📊 Monthly Tracker'!V8,'📊 Monthly Tracker'!Y8,'📊 Monthly Tracker'!AB8),"") -> 0 | F4: =IFERROR(SUM('📊 Monthly Tracker'!AE8,'📊 Monthly Tracker'!AH8,'📊 Monthly Tracker'!AK8),"") -> 0 | G4: =IFERROR(SUM('📊 Monthly Tracker'!D8,'📊 Monthly Tracker'!G8,'📊 Monthly Tracker'!J8,'📊 Monthly Tracker'!M8,'📊 Monthly Tracker'!P8,'📊 Monthly Tracker'!S8,'📊 Monthly Tracker'!V8,'📊 Monthly Tracker'!Y8,'📊 Monthly Tracker'!AB8,'📊 Monthly Tracker'!AE8,'📊 Monthly Tracker'!AH8,'📊 Monthly Tracker'!AK8),"") -> 5 | H4: ='📊 Monthly Tracker'!AJ8 -> 111 | I4: =IFERROR(IF(H4=0,"—",IF(G4="","",G4/H4)),"—") -> 0.045045045
A5: SQL (дзвінки / Demo), шт. | B5: 280–360 | C5: =IFERROR(SUM('📊 Monthly Tracker'!D9,'📊 Monthly Tracker'!G9,'📊 Monthly Tracker'!J9),"") -> 0.773 | D5: =IFERROR(SUM('📊 Monthly Tracker'!M9,'📊 Monthly Tracker'!P9,'📊 Monthly Tracker'!S9),"") -> 0 | E5: =IFERROR(SUM('📊 Monthly Tracker'!V9,'📊 Monthly Tracker'!Y9,'📊 Monthly Tracker'!AB9),"") -> 0 | F5: =IFERROR(SUM('📊 Monthly Tracker'!AE9,'📊 Monthly Tracker'!AH9,'📊 Monthly Tracker'!AK9),"") -> 0 | G5: =IFERROR(SUM('📊 Monthly Tracker'!D9,'📊 Monthly Tracker'!G9,'📊 Monthly Tracker'!J9,'📊 Monthly Tracker'!M9,'📊 Monthly Tracker'!P9,'📊 Monthly Tracker'!S9,'📊 Monthly Tracker'!V9,'📊 Monthly Tracker'!Y9,'📊 Monthly Tracker'!AB9,'📊 Monthly Tracker'!AE9,'📊 Monthly Tracker'!AH9,'📊 Monthly Tracker'!AK9),"") -> 0.773 | H5: ='📊 Monthly Tracker'!AJ9 -> 0.65 | I5: =IFERROR(IF(H5=0,"—",IF(G5="","",G5/H5)),"—") -> 1.1892308
A6: Нових платних клієнтів, шт. | B6: 115–130 | C6: =IFERROR(SUM('📊 Monthly Tracker'!D10,'📊 Monthly Tracker'!G10,'📊 Monthly Tracker'!J10),"") -> 0.242 | D6: =IFERROR(SUM('📊 Monthly Tracker'!M10,'📊 Monthly Tracker'!P10,'📊 Monthly Tracker'!S10),"") -> 0 | E6: =IFERROR(SUM('📊 Monthly Tracker'!V10,'📊 Monthly Tracker'!Y10,'📊 Monthly Tracker'!AB10),"") -> 0 | F6: =IFERROR(SUM('📊 Monthly Tracker'!AE10,'📊 Monthly Tracker'!AH10,'📊 Monthly Tracker'!AK10),"") -> 0 | G6: =IFERROR(SUM('📊 Monthly Tracker'!D10,'📊 Monthly Tracker'!G10,'📊 Monthly Tracker'!J10,'📊 Monthly Tracker'!M10,'📊 Monthly Tracker'!P10,'📊 Monthly Tracker'!S10,'📊 Monthly Tracker'!V10,'📊 Monthly Tracker'!Y10,'📊 Monthly Tracker'!AB10,'📊 Monthly Tracker'!AE10,'📊 Monthly Tracker'!AH10,'📊 Monthly Tracker'!AK10),"") -> 0.242 | H6: ='📊 Monthly Tracker'!AJ10 -> 0.23 | I6: =IFERROR(IF(H6=0,"—",IF(G6="","",G6/H6)),"—") -> 1.0521739
A7: Накопич. клієнтів наприкінці | B7: 115–130+ | C7: =IFERROR('📊 Monthly Tracker'!J11,"") | D7: =IFERROR('📊 Monthly Tracker'!S11,"") | E7: =IFERROR('📊 Monthly Tracker'!AB11,"") | F7: =IFERROR('📊 Monthly Tracker'!AK11,"") | G7: =IFERROR('📊 Monthly Tracker'!AK11,"") | H7: ='📊 Monthly Tracker'!AJ11 -> 0.4 | I7: =IFERROR(IF(H7=0,"—",IF(G7="","",G7/H7)),"—")
A8: CAC зведений (сер.), USD | B8: ≤$260 | C8: =IFERROR(AVERAGE('📊 Monthly Tracker'!D15,'📊 Monthly Tracker'!G15,'📊 Monthly Tracker'!J15),"") | D8: =IFERROR(AVERAGE('📊 Monthly Tracker'!M15,'📊 Monthly Tracker'!P15,'📊 Monthly Tracker'!S15),"") | E8: =IFERROR(AVERAGE('📊 Monthly Tracker'!V15,'📊 Monthly Tracker'!Y15,'📊 Monthly Tracker'!AB15),"") | F8: =IFERROR(AVERAGE('📊 Monthly Tracker'!AE15,'📊 Monthly Tracker'!AH15,'📊 Monthly Tracker'!AK15),"") | G8: =IFERROR(AVERAGE('📊 Monthly Tracker'!D15,'📊 Monthly Tracker'!G15,'📊 Monthly Tracker'!J15,'📊 Monthly Tracker'!M15,'📊 Monthly Tracker'!P15,'📊 Monthly Tracker'!S15,'📊 Monthly Tracker'!V15,'📊 Monthly Tracker'!Y15,'📊 Monthly Tracker'!AB15,'📊 Monthly Tracker'!AE15,'📊 Monthly Tracker'!AH15,'📊 Monthly Tracker'!AK15),"") | H8: ='📊 Monthly Tracker'!AJ15 -> 4.5 | I8: =IFERROR(IF(H8=0,"—",IF(G8="","",G8/H8)),"—")
A9: CPL середній, USD | B9: ≤$35 | C9: =IFERROR(AVERAGE('📊 Monthly Tracker'!D16,'📊 Monthly Tracker'!G16,'📊 Monthly Tracker'!J16),"") -> 0.0874 | D9: =IFERROR(AVERAGE('📊 Monthly Tracker'!M16,'📊 Monthly Tracker'!P16,'📊 Monthly Tracker'!S16),"") | E9: =IFERROR(AVERAGE('📊 Monthly Tracker'!V16,'📊 Monthly Tracker'!Y16,'📊 Monthly Tracker'!AB16),"") | F9: =IFERROR(AVERAGE('📊 Monthly Tracker'!AE16,'📊 Monthly Tracker'!AH16,'📊 Monthly Tracker'!AK16),"") | G9: =IFERROR(AVERAGE('📊 Monthly Tracker'!D16,'📊 Monthly Tracker'!G16,'📊 Monthly Tracker'!J16,'📊 Monthly Tracker'!M16,'📊 Monthly Tracker'!P16,'📊 Monthly Tracker'!S16,'📊 Monthly Tracker'!V16,'📊 Monthly Tracker'!Y16,'📊 Monthly Tracker'!AB16,'📊 Monthly Tracker'!AE16,'📊 Monthly Tracker'!AH16,'📊 Monthly Tracker'!AK16),"") -> 0.0874 | H9: ='📊 Monthly Tracker'!AJ16 -> 0.03 | I9: =IFERROR(IF(H9=0,"—",IF(G9="","",G9/H9)),"—") -> 2.9133333
A10: Витрати на рекламу РАЗОМ, USD | B10: $18,000 | C10: =IFERROR(SUM('📊 Monthly Tracker'!D17,'📊 Monthly Tracker'!G17,'📊 Monthly Tracker'!J17),"") -> 3 | D10: =IFERROR(SUM('📊 Monthly Tracker'!M17,'📊 Monthly Tracker'!P17,'📊 Monthly Tracker'!S17),"") -> 0 | E10: =IFERROR(SUM('📊 Monthly Tracker'!V17,'📊 Monthly Tracker'!Y17,'📊 Monthly Tracker'!AB17),"") -> 0 | F10: =IFERROR(SUM('📊 Monthly Tracker'!AE17,'📊 Monthly Tracker'!AH17,'📊 Monthly Tracker'!AK17),"") -> 0 | G10: =IFERROR(SUM('📊 Monthly Tracker'!D17,'📊 Monthly Tracker'!G17,'📊 Monthly Tracker'!J17,'📊 Monthly Tracker'!M17,'📊 Monthly Tracker'!P17,'📊 Monthly Tracker'!S17,'📊 Monthly Tracker'!V17,'📊 Monthly Tracker'!Y17,'📊 Monthly Tracker'!AB17,'📊 Monthly Tracker'!AE17,'📊 Monthly Tracker'!AH17,'📊 Monthly Tracker'!AK17),"") -> 3 | H10: ='📊 Monthly Tracker'!AJ17 -> 420 | I10: =IFERROR(IF(H10=0,"—",IF(G10="","",G10/H10)),"—") -> 0.0071428571
A11: CTR платної реклами (сер.), % | B11: 1.5–3% | C11: =IFERROR(AVERAGE('📊 Monthly Tracker'!D19,'📊 Monthly Tracker'!G19,'📊 Monthly Tracker'!J19),"") -> 0 | D11: =IFERROR(AVERAGE('📊 Monthly Tracker'!M19,'📊 Monthly Tracker'!P19,'📊 Monthly Tracker'!S19),"") | E11: =IFERROR(AVERAGE('📊 Monthly Tracker'!V19,'📊 Monthly Tracker'!Y19,'📊 Monthly Tracker'!AB19),"") | F11: =IFERROR(AVERAGE('📊 Monthly Tracker'!AE19,'📊 Monthly Tracker'!AH19,'📊 Monthly Tracker'!AK19),"") | G11: =IFERROR(AVERAGE('📊 Monthly Tracker'!D19,'📊 Monthly Tracker'!G19,'📊 Monthly Tracker'!J19,'📊 Monthly Tracker'!M19,'📊 Monthly Tracker'!P19,'📊 Monthly Tracker'!S19,'📊 Monthly Tracker'!V19,'📊 Monthly Tracker'!Y19,'📊 Monthly Tracker'!AB19,'📊 Monthly Tracker'!AE19,'📊 Monthly Tracker'!AH19,'📊 Monthly Tracker'!AK19),"") -> 0 | H11: ='📊 Monthly Tracker'!AJ19 -> 200 | I11: =IFERROR(IF(H11=0,"—",IF(G11="","",G11/H11)),"—") -> 0
A12: ER соцмереж (сер.), % | B12: 3–6% | C12: =IFERROR(AVERAGE('📊 Monthly Tracker'!D26,'📊 Monthly Tracker'!G26,'📊 Monthly Tracker'!J26),"") | D12: =IFERROR(AVERAGE('📊 Monthly Tracker'!M26,'📊 Monthly Tracker'!P26,'📊 Monthly Tracker'!S26),"") | E12: =IFERROR(AVERAGE('📊 Monthly Tracker'!V26,'📊 Monthly Tracker'!Y26,'📊 Monthly Tracker'!AB26),"") | F12: =IFERROR(AVERAGE('📊 Monthly Tracker'!AE26,'📊 Monthly Tracker'!AH26,'📊 Monthly Tracker'!AK26),"") | G12: =IFERROR(AVERAGE('📊 Monthly Tracker'!D26,'📊 Monthly Tracker'!G26,'📊 Monthly Tracker'!J26,'📊 Monthly Tracker'!M26,'📊 Monthly Tracker'!P26,'📊 Monthly Tracker'!S26,'📊 Monthly Tracker'!V26,'📊 Monthly Tracker'!Y26,'📊 Monthly Tracker'!AB26,'📊 Monthly Tracker'!AE26,'📊 Monthly Tracker'!AH26,'📊 Monthly Tracker'!AK26),"") | H12: ='📊 Monthly Tracker'!AJ26 -> 10 | I12: =IFERROR(IF(H12=0,"—",IF(G12="","",G12/H12)),"—")
A13: Підписники наприкінці | B13: 7,000+ | C13: =IFERROR('📊 Monthly Tracker'!J27,"") | D13: =IFERROR('📊 Monthly Tracker'!S27,"") | E13: =IFERROR('📊 Monthly Tracker'!AB27,"") | F13: =IFERROR('📊 Monthly Tracker'!AK27,"") | G13: =IFERROR('📊 Monthly Tracker'!AK27,"") | H13: ='📊 Monthly Tracker'!AJ27 -> 8 | I13: =IFERROR(IF(H13=0,"—",IF(G13="","",G13/H13)),"—")
A14: Статей у блозі (накопич.) | B14: 38+ | C14: =IFERROR('📊 Monthly Tracker'!J28,"") | D14: =IFERROR('📊 Monthly Tracker'!S28,"") | E14: =IFERROR('📊 Monthly Tracker'!AB28,"") | F14: =IFERROR('📊 Monthly Tracker'!AK28,"") | G14: =IFERROR('📊 Monthly Tracker'!AK28,"") | H14: ='📊 Monthly Tracker'!AJ28 -> 0.4 | I14: =IFERROR(IF(H14=0,"—",IF(G14="","",G14/H14)),"—")
A15: Кейс-стаді (накопич.) | B15: 8–10 | C15: =IFERROR('📊 Monthly Tracker'!J29,"") | D15: =IFERROR('📊 Monthly Tracker'!S29,"") | E15: =IFERROR('📊 Monthly Tracker'!AB29,"") | F15: =IFERROR('📊 Monthly Tracker'!AK29,"") | G15: =IFERROR('📊 Monthly Tracker'!AK29,"") | H15: ='📊 Monthly Tracker'!AJ29 -> 0.1 | I15: =IFERROR(IF(H15=0,"—",IF(G15="","",G15/H15)),"—")
A16: Email Open Rate (сер.), % | B16: ≥35% | C16: =IFERROR(AVERAGE('📊 Monthly Tracker'!D31,'📊 Monthly Tracker'!G31,'📊 Monthly Tracker'!J31),"") | D16: =IFERROR(AVERAGE('📊 Monthly Tracker'!M31,'📊 Monthly Tracker'!P31,'📊 Monthly Tracker'!S31),"") | E16: =IFERROR(AVERAGE('📊 Monthly Tracker'!V31,'📊 Monthly Tracker'!Y31,'📊 Monthly Tracker'!AB31),"") | F16: =IFERROR(AVERAGE('📊 Monthly Tracker'!AE31,'📊 Monthly Tracker'!AH31,'📊 Monthly Tracker'!AK31),"") | G16: =IFERROR(AVERAGE('📊 Monthly Tracker'!D31,'📊 Monthly Tracker'!G31,'📊 Monthly Tracker'!J31,'📊 Monthly Tracker'!M31,'📊 Monthly Tracker'!P31,'📊 Monthly Tracker'!S31,'📊 Monthly Tracker'!V31,'📊 Monthly Tracker'!Y31,'📊 Monthly Tracker'!AB31,'📊 Monthly Tracker'!AE31,'📊 Monthly Tracker'!AH31,'📊 Monthly Tracker'!AK31),"") | H16: ='📊 Monthly Tracker'!AJ31 -> 30 | I16: =IFERROR(IF(H16=0,"—",IF(G16="","",G16/H16)),"—")
A17: Відгуки / Рекомендації | B17: 20–30 | C17: =IFERROR('📊 Monthly Tracker'!J34,"") | D17: =IFERROR('📊 Monthly Tracker'!S34,"") | E17: =IFERROR('📊 Monthly Tracker'!AB34,"") | F17: =IFERROR('📊 Monthly Tracker'!AK34,"") | G17: =IFERROR('📊 Monthly Tracker'!AK34,"") | H17: ='📊 Monthly Tracker'!AJ34 | I17: =IFERROR(IF(H17=0,"—",IF(G17="","",G17/H17)),"—") -> —
A18: Партнерства | B18: 5–10 | C18: =IFERROR('📊 Monthly Tracker'!J35,"") | D18: =IFERROR('📊 Monthly Tracker'!S35,"") | E18: =IFERROR('📊 Monthly Tracker'!AB35,"") | F18: =IFERROR('📊 Monthly Tracker'!AK35,"") | G18: =IFERROR('📊 Monthly Tracker'!AK35,"") | H18: ='📊 Monthly Tracker'!AJ35 | I18: =IFERROR(IF(H18=0,"—",IF(G18="","",G18/H18)),"—") -> —
